<?xml version="1.0"?>
<robot xmlns:xacro="http://www.ros.org/wiki/xacro"  name="robot">

    <link name="world"></link>
    <joint name="base_joint" type="fixed">
        <origin xyz="1 1 0" rpy="0 0 0"/>
        <parent link="world"/>
        <child link="base_link"/>        
    </joint>
    <link name="base_link">
        <visual>
            <origin xyz="0 0 0.2225" rpy="0 0 0"/>
            <geometry>
                <box size="0.1 0.062 0.445" />
            </geometry>
            <material name="green">
                <color rgba="0.2 1 0.2 1"/>
            </material>
        </visual>
        <inertial>
            <origin xyz="0 0 0" rpy="0 0 0"/>
            <mass value="12" />
            <inertia ixx="2.26" ixy="0.0" ixz="0.0" iyy="6.26" iyz="0.0" izz="8.5" />
        </inertial>
    </link>
    <joint name="sl" type="prismatic">
        <origin xyz="0 0 0.445" rpy="0 0 0"/>
        <parent link="base_link"/>
        <child link="slider_link"/>     
        <axis xyz="0 0 1"/>
        <limit lower="-0.445" upper="0" velocity="100" effort="100"/>    
    </joint>
    <link name="slider_link">
        <visual>
            <origin xyz="0 0.049 0" rpy="0 0 0"/>
            <geometry>
                <box size="0.062 0.039 0.052" />
            </geometry>
            <material name="green">
                <color rgba="0.2 1 0.2 1"/>
            </material>
        </visual>
        <inertial>
            <origin xyz="0 0 0" rpy="0 0 0"/>
            <mass value="12" />
            <inertia ixx="2.26" ixy="0.0" ixz="0.0" iyy="6.26" iyz="0.0" izz="8.5" />
        </inertial>
    </link>
    <joint name="sh" type="revolute">
        <origin xyz="0 0.06 0" rpy="0 0 0"/>
        <parent link="slider_link"/>
        <child link="sh_link"/>
        <axis xyz="0 0 1"/>
        <limit lower="1.5708" upper="-1.5708" velocity="0.5" effort="1000"/> 
    </joint>
    <link name="sh_link">
        <visual>
            <origin xyz="0 0.1525 0" rpy="0 0 0"/>
            <geometry>
                <box size="0.032 0.185 0.01" />
            </geometry>
            <material name="green">
                <color rgba="0.2 1 0.2 1"/>
            </material>
        </visual>
        <inertial>
            <origin xyz="0 0 0" rpy="0 0 0"/>
            <mass value="12" />
            <inertia ixx="2.26" ixy="0.0" ixz="0.0" iyy="6.26" iyz="0.0" izz="8.5" />
        </inertial>
    </link>
    <joint name="el" type="revolute">
        <origin xyz="0 0.245 0" rpy="0 0 0"/>
        <parent link="sh_link"/>
        <child link="el_link"/>
        <axis xyz="0 0 1"/>
        <limit lower="1.5708" upper="-1.5708" velocity="0.5" effort="1000"/> 
    </joint>
    <link name="el_link">
        <visual>
            <origin xyz="0 0.0925 0" rpy="0 0 0"/>
            <geometry>
                <box size="0.032 0.185 0.01" />
            </geometry>
            <material name="green">
                <color rgba="0.2 1 0.2 1"/>
            </material>
        </visual>
        <inertial>
            <origin xyz="0 0 0" rpy="0 0 0"/>
            <mass value="12" />
            <inertia ixx="2.26" ixy="0.0" ixz="0.0" iyy="6.26" iyz="0.0" izz="8.5" />
        </inertial>
    </link> 
    <joint name="cl" type="revolute">
        <origin xyz="0 0 0" rpy="0 0 0"/>
        <parent link="el_link"/>
        <child link="cl_link"/>
        <axis xyz="0 0 1"/>
        <limit lower="1.5708" upper="-1.5708" velocity="0.5" effort="1000"/> 
    </joint>
    <link name="cl_link">
        <visual>
            <origin xyz="0 0 0" rpy="0 0 0"/>
            <geometry>
                <box size="0.01 0.01 0.01" />
            </geometry>
            <material name="green">
                <color rgba="0.2 1 0.2 1"/>
            </material>
        </visual>
        <inertial>
            <origin xyz="0 0 0" rpy="0 0 0"/>
            <mass value="12" />
            <inertia ixx="2.26" ixy="0.0" ixz="0.0" iyy="6.26" iyz="0.0" izz="8.5" />
        </inertial>
    </link> 
    
</robot>
